Workbook
Name Slicer_Country: #N/A

Sheet Data
C1: Employee Data
C5: Name | D5: Gender | E5: Department | F5: Age | G5: Date Joined | H5: Salary | I5: Rating
C6: Lindy Guillet | D6: Male | E6: Sales | F6: 22 | G6: 44446 | H6: 112780 | I6: Above average
C7: Ambros Murthwaite | D7: Male | E7: Procurement | F7: 46 | G7: 44758 | H7: 70610 | I7: Average
C8: Tatum Hush | D8: Female | E8: Sales | F8: 28 | G8: 44357 | H8: 53240 | I8: Average
C9: Benny Karolovsky | E9: Finance | F9: 37 | G9: 44146 | H9: 115440 | I9: Poor
C10: Hoyt D'Alesco | D10: Male | E10: Sales | F10: 32 | G10: 44465 | H10: 53540 | I10: Average
C11: Halimeda Kuscha | D11: Female | E11: Procurement | F11: 30 | G11: 44861 | H11: 112570 | I11: Average
C12: Erin Androsik | D12: Male | E12: Procurement | F12: 33 | G12: 44701 | H12: 48530 | I12: Above average
C13: Vic Radolf | D13: Female | E13: Website | F13: 24 | G13: 44148 | H13: 62780 | I13: Average
C14: William Reeveley | D14: Male | E14: Website | F14: 33 | G14: 44509 | H14: 53870 | I14: Average
C15: Ewart Laphorn | D15: Female | E15: HR | F15: 27 | G15: 44122 | H15: 119110 | I15: Average
C16: Bev Lashley | D16: Male | E16: Website | F16: 29 | G16: 44180 | H16: 112110 | I16: Poor
C17: Kath Bletsoe | D17: Male | E17: Sales | F17: 25 | G17: 44383 | H17: 65700 | I17: Average
C18: Murry Dryburgh | D18: Male | E18: Website | F18: 37 | G18: 44701 | H18: 69070 | I18: Average
C19: Kaine Padly | D19: Male | E19: Website | F19: 20 | G19: 44459 | H19: 107700 | I19: Average
C20: Kassi Jonson | D20: Female | E20: Website | F20: 32 | G20: 44354 | H20: 43840 | I20: Above average
C21: Simon Kembery | D21: Male | E21: Procurement | F21: 40 | G21: 44263 | H21: 99750 | I21: Average
... C29: Esmaria Denecamp | D29: Male | E29: Finance | F29: 27 | G29: 44567 | H29: 48980 | I29: Average
C30: Curtice Advani | E30: Finance | F30: 30 | G30: 44597 | H30: 64000 | I30: Average
C31: Barr Faughny | D31: Female | E31: Procurement | F31: 42 | G31: 44779 | H31: 75000 | I31: Exceptional
C32: Merrilee Plenty | D32: Female | E32: Website | F32: 40 | G32: 44337 | H32: 87620 | I32: Average
C33: Niall Selesnick | D33: Female | E33: Website | F33: 29 | G33: 44023 | H33: 34980 | I33: Average
C34: Beverie Moffet | D34: Female | E34: Finance | F34: 28 | G34: 44185 | H34: 75970 | I34: Average
C35: Jehu Rudeforth | D35: Female | E35: Finance | F35: 34 | G35: 44612 | H35: 60130 | I35: Average
C36: Camilla Castle | D36: Female | E36: Website | F36: 33 | G36: 44374 | H36: 75480 | I36: Very poor
C37: Roddy Speechley | D37: Male | E37: Procurement | F37: 33 | G37: 44164 | H37: 115920 | I37: Average
C38: Gray Seamon | D38: Female | E38: Sales | F38: 36 | G38: 44494 | H38: 78540 | I38: Average
C39: Madelene Upcott | D39: Male | E39: Procurement | F39: 25 | G39: 44726 | H39: 109190 | I39: Above average
C40: Violante Courtonne | D40: Female | E40: Sales | F40: 34 | G40: 44721 | H40: 49630 | I40: Poor
C41: Bernie Gorges | D41: Female | E41: Procurement | F41: 28 | G41: 44630 | H41: 99970 | I41: Average
C42: Torrance Collier | D42: Female | E42: Website | F42: 33 | G42: 44190 | H42: 96140 | I42: Average
... C67: Wilone O'Kielt | D67: Female | E67: Website | F67: 43 | G67: 45045 | H67: 114870 | I67: Average
C68: Madge McCloughen | E68: Website | F68: 32 | G68: 44774 | H68: 91310 | I68: Average
C69: Janene Hairsine | D69: Female | E69: Procurement | F69: 28 | G69: 44486 | H69: 104770 | I69: Average
C70: Alta Kaszper | D70: Male | E70: Sales | F70: 27 | G70: 44134 | H70: 54970 | I70: Average
C71: Dennison Crosswaite | E71: Website | F71: 26 | G71: 44271 | H71: 90700 | I71: Above average
C72: Oran Buxcy | D72: Female | E72: Sales | F72: 38 | G72: 44329 | H72: 56870 | I72: Above average
C73: Hinda Label | D73: Female | E73: Sales | F73: 25 | G73: 44205 | H73: 92700 | I73: Average
C74: Marney O'Breen | D74: Female | E74: Finance | F74: 21 | G74: 44317 | H74: 65920 | I74: Average
...

Sheet India Staff
B2: Name | C2: Gender | D2: Age | E2: Rating | F2: Date Joined | G2: Department | H2: Salary
B3: Deepali Charan | C3: Male | D3: 20 | E3: Average | F3: 44122 | G3: Website | H3: 112650
B4: Yagna Sujeev | C4: Female | D4: 32 | E4: Above average | F4: 44293 | G4: Website | H4: 43840
B5: Satyendra Venkatadri | C5: Male | D5: 31 | E5: Average | F5: 44663 | G5: Procurement | H5: 103550
B6: Madhavdas Buhpathi | C6: Female | D6: 32 | E6: Average | F6: 44339 | G6: HR | H6: 45510
B7: Sahila Chandrasekhar | D7: 37 | E7: Poor | F7: 44085 | G7: Finance | H7: 115440
B8: Mirium Seemantini Shivakumar | C8: Female | D8: 38 | E8: Above average | F8: 44268 | G8: Sales | H8: 56870
B9: Purnendu Vijayarangan | C9: Female | D9: 25 | E9: Average | F9: 44144 | G9: Sales | H9: 92700
B10: Rukma Vinita | D10: 32 | E10: Average | F10: 44713 | G10: Website | H10: 91310
B11: Yauvani Tarpa | C11: Male | D11: 33 | E11: Average | F11: 44324 | G11: Sales | H11: 74550
B12: Damayanti Thangavadivelu | C12: Male | D12: 25 | E12: Above average | F12: 44665 | G12: Procurement | H12: 109190
B13: Manjusri Ruchi | C13: Female | D13: 40 | E13: Average | F13: 44320 | G13: Website | H13: 104410
B14: Mithil Nadkarni | C14: Male | D14: 30 | E14: Average | F14: 44544 | G14: Finance | H14: 96800
B15: Ardhendu Abhichandra Jayakar | C15: Male | D15: 28 | E15: Above average | F15: 43980 | G15: Finance | H15: 48170
B16: Akbar Sorabhjee | C16: Male | D16: 21 | E16: Average | F16: 44042 | G16: Procurement | H16: 37920
B17: Bandhula Sathyanna | C17: Male | D17: 34 | E17: Average | F17: 44642 | G17: Procurement | H17: 112650
B18: Daruka Ghazali | C18: Female | D18: 34 | E18: Poor | F18: 44660 | G18: Sales | H18: 49630
B19: Heer Pennathur | C19: Male | D19: 36 | E19: Average | F19: 43958 | G19: Website | H19: 118840
B20: Shekhar Eswara | C20: Male | D20: 30 | E20: Average | F20: 44789 | G20: Website | H20: 69710
B21: Udyan Lanka | C21: Male | D21: 20 | E21: Average | F21: 44683 | G21: Procurement | H21: 79570
B22: Shreela Ramasubraman | C22: Female | D22: 22 | E22: Above average | F22: 44388 | G22: Procurement | H22: 76900
... B53: Indu Varada Sumedh | C53: Female | D53: 28 | E53: Average | F53: 44124 | G53: Finance | H53: 75970
B54: Karuna Pashupathy | D54: 27 | E54: Above average | F54: 44212 | G54: Website | H54: 90700
B55: Mardav Ramaswami | C55: Male | D55: 30 | E55: Average | F55: 44607 | G55: Procurement | H55: 60570
B56: Sarayu Ragunathan | C56: Male | D56: 33 | E56: Average | F56: 44103 | G56: Procurement | H56: 115920
B57: Kevalkumar Solanki | C57: Female | D57: 33 | E57: Average | F57: 44006 | G57: Finance | H57: 65360
B58: Upendra Swati | D58: 30 | E58: Average | F58: 44535 | G58: Finance | H58: 64000
B59: Deepit Ranjana | C59: Female | D59: 34 | E59: Average | F59: 44383 | G59: Finance | H59: 92450
B60: Amal Nimesh | C60: Male | D60: 31 | E60: Average | F60: 44450 | G60: Website | H60: 48950
B61: Kunja Prashanta Vibha | C61: Female | D61: 27 | E61: Average | F61: 44625 | G61: Website | H61: 83750
B62: Godavari Veena | C62: Female | D62: 40 | E62: Average | F62: 44276 | G62: Website | H62: 87620
B63: Devasree Fullara Saurin | C63: Female | D63: 20 | E63: Poor | F63: 44476 | G63: Sales | H63: 68900
B64: Geena Raghavanpillai | C64: Male | D64: 32 | E64: Average | F64: 44403 | G64: Sales | H64: 53540
B65: Rupak Mehra | C65: Male | D65: 28 | E65: Very poor | F65: 44758 | G65: Sales | H65: 43510
B66: Sawini Chandan | C66: Female | D66: 38 | E66: Exceptional | F66: 44316 | G66: Sales | H66: 109160
B67: Baruna Ogale | C67: Male | D67: 40 | E67: Average | F67: 44204 | G67: Procurement | H67: 99750
B68: Jagajeet Viraj | C68: Female | D68: 31 | E68: Average | F68: 44084 | G68: Website | H68: 41980
B69: Kulbhushan Moorthy | C69: Male | D69: 36 | E69: Average | F69: 44272 | G69: Finance | H69: 71380
B70: Ilesh Dasgupta | C70: Male | D70: 27 | E70: Very poor | F70: 44547 | G70: Procurement | H70: 113280
... B98: Madhavdas Buhpathi | C98: Female | D98: 32 | E98: Average | F98: 44339 | G98: HR | H98: 45510
...

Sheet All Staff
B1: Name | C1: Gender | D1: Age | E1: Rating | F1: Date Joined | G1: Department | H1: Salary | I1: Country | J1: Tenure | K1: Bonus | L1: Rating Value using IFS | M1: Rating using Lookup | O1: Basic Understanding: | Q1: Median Check to see for Skew
B2: Gretchen Callow | C2: Female | D2: 21 | E2: Average | F2: 44678 | G2: Website | H2: 33920 | I2: NZ | J2: =(TODAY() - staff[[#This Row],[Date Joined]]) / 365 -> 3.6219178 | K2: =ROUNDUP(IF(staff[[#This Row],[Tenure]]>2, 3%, 2%) * staff[[#This Row],[Salary]],0) -> 1018 | L2: {=_xlfn.IFS(staff[[#This Row],[Rating]]="Exceptional", 5, staff[[#This Row],[Rating]]="Above average", 4, staff[[#This Row],[Rating]]="Average", 3, staff[[#This Row],[Rating]]="Poor", 2, staff[[#This Row],[Rating]]="Very poor", 1)} -> 3 | M2: =_xlfn.XLOOKUP(staff[[#This Row],[Rating]],'Lookup Array'!$A$1:$A$5, 'Lookup Array'!$B$1:$B$5, "No Rating") -> 3 | O2: Count of Employees: | P2: =COUNTA(staff[Name]) -> 183
B3: Shubhra Potla | C3: Female | D3: 21 | E3: Average | F3: 44619 | G3: Website | H3: 33920 | I3: IND | J3: =(TODAY() - staff[[#This Row],[Date Joined]]) / 365 -> 3.7835616 | K3: =ROUNDUP(IF(staff[[#This Row],[Tenure]]>2, 3%, 2%) * staff[[#This Row],[Salary]],0) -> 1018 | L3: {=_xlfn.IFS(staff[[#This Row],[Rating]]="Exceptional", 5, staff[[#This Row],[Rating]]="Above average", 4, staff[[#This Row],[Rating]]="Average", 3, staff[[#This Row],[Rating]]="Poor", 2, staff[[#This Row],[Rating]]="Very poor", 1)} -> 3 | M3: =_xlfn.XLOOKUP(staff[[#This Row],[Rating]],'Lookup Array'!$A$1:$A$5, 'Lookup Array'!$B$1:$B$5, "No Rating") -> 3 | O3: Average Salary: | P3: =AVERAGE(staff[Salary]) -> 77173.716 | Q3: =MEDIAN(staff[Salary]) -> 75000
B4: Niall Selesnick | C4: Female | D4: 29 | E4: Average | F4: 44023 | G4: Website | H4: 34980 | I4: NZ | J4: =(TODAY() - staff[[#This Row],[Date Joined]]) / 365 -> 5.4164384 | K4: =ROUNDUP(IF(staff[[#This Row],[Tenure]]>2, 3%, 2%) * staff[[#This Row],[Salary]],0) -> 1050 | L4: {=_xlfn.IFS(staff[[#This Row],[Rating]]="Exceptional", 5, staff[[#This Row],[Rating]]="Above average", 4, staff[[#This Row],[Rating]]="Average", 3, staff[[#This Row],[Rating]]="Poor", 2, staff[[#This Row],[Rating]]="Very poor", 1)} -> 3 | M4: =_xlfn.XLOOKUP(staff[[#This Row],[Rating]],'Lookup Array'!$A$1:$A$5, 'Lookup Array'!$B$1:$B$5, "No Rating") -> 3 | O4: Average Age: | P4: =AVERAGE(staff[Age]) -> 30.42623 | Q4: =MEDIAN(staff[Age]) -> 30
B5: Suchira Bhanupriya Tapti | C5: Female | D5: 29 | E5: Average | F5: 43962 | G5: Website | H5: 34980 | I5: IND | J5: =(TODAY() - staff[[#This Row],[Date Joined]]) / 365 -> 5.5835616 | K5: =ROUNDUP(IF(staff[[#This Row],[Tenure]]>2, 3%, 2%) * staff[[#This Row],[Salary]],0) -> 1050 | L5: {=_xlfn.IFS(staff[[#This Row],[Rating]]="Exceptional", 5, staff[[#This Row],[Rating]]="Above average", 4, staff[[#This Row],[Rating]]="Average", 3, staff[[#This Row],[Rating]]="Poor", 2, staff[[#This Row],[Rating]]="Very poor", 1)} -> 3 | M5: =_xlfn.XLOOKUP(staff[[#This Row],[Rating]],'Lookup Array'!$A$1:$A$5, 'Lookup Array'!$B$1:$B$5, "No Rating") -> 3 | O5: Average Tenure: | P5: =AVERAGE(staff[Tenure]) -> 4.2930609
B6: Bili Sizey | C6: Male | D6: 43 | E6: Average | F6: 44620 | G6: Sales | H6: 36040 | I6: NZ | J6: =(TODAY() - staff[[#This Row],[Date Joined]]) / 365 -> 3.7808219 | K6: =ROUNDUP(IF(staff[[#This Row],[Tenure]]>2, 3%, 2%) * staff[[#This Row],[Salary]],0) -> 1082 | L6: {=_xlfn.IFS(staff[[#This Row],[Rating]]="Exceptional", 5, staff[[#This Row],[Rating]]="Above average", 4, staff[[#This Row],[Rating]]="Average", 3, staff[[#This Row],[Rating]]="Poor", 2, staff[[#This Row],[Rating]]="Very poor", 1)} -> 3 | M6: =_xlfn.XLOOKUP(staff[[#This Row],[Rating]],'Lookup Array'!$A$1:$A$5, 'Lookup Array'!$B$1:$B$5, "No Rating") -> 3
B7: Waheeda Vasuman | C7: Male | D7: 43 | E7: Average | F7: 44558 | G7: Sales | H7: 36040 | I7: IND | J7: =(TODAY() - staff[[#This Row],[Date Joined]]) / 365 -> 3.9506849 | K7: =ROUNDUP(IF(staff[[#This Row],[Tenure]]>2, 3%, 2%) * staff[[#This Row],[Salary]],0) -> 1082 | L7: {=_xlfn.IFS(staff[[#This Row],[Rating]]="Exceptional", 5, staff[[#This Row],[Rating]]="Above average", 4, staff[[#This Row],[Rating]]="Average", 3, staff[[#This Row],[Rating]]="Poor", 2, staff[[#This Row],[Rating]]="Very poor", 1)} -> 3 | M7: =_xlfn.XLOOKUP(staff[[#This Row],[Rating]],'Lookup Array'!$A$1:$A$5, 'Lookup Array'!$B$1:$B$5, "No Rating") -> 3 | O7: Female Count | P7: =COUNTIFS(staff[Gender], "Female") -> 86
B8: Orton Livick | C8: Male | D8: 21 | E8: Average | F8: 44104 | G8: Procurement | H8: 37920 | I8: NZ | J8: =(TODAY() - staff[[#This Row],[Date Joined]]) / 365 -> 5.1945205 | K8: =ROUNDUP(IF(staff[[#This Row],[Tenure]]>2, 3%, 2%) * staff[[#This Row],[Salary]],0) -> 1138 | L8: {=_xlfn.IFS(staff[[#This Row],[Rating]]="Exceptional", 5, staff[[#This Row],[Rating]]="Above average", 4, staff[[#This Row],[Rating]]="Average", 3, staff[[#This Row],[Rating]]="Poor", 2, staff[[#This Row],[Rating]]="Very poor", 1)} -> 3 | M8: =_xlfn.XLOOKUP(staff[[#This Row],[Rating]],'Lookup Array'!$A$1:$A$5, 'Lookup Array'!$B$1:$B$5, "No Rating") -> 3 | O8: % Female in company | P8: =P7 / P2 -> 0.46994536
B9: Akbar Sorabhjee | C9: Male | D9: 21 | E9: Average | F9: 44042 | G9: Procurement | H9: 37920 | I9: IND | J9: =(TODAY() - staff[[#This Row],[Date Joined]]) / 365 -> 5.3643836 | K9: =ROUNDUP(IF(staff[[#This Row],[Tenure]]>2, 3%, 2%) * staff[[#This Row],[Salary]],0) -> 1138 | L9: {=_xlfn.IFS(staff[[#This Row],[Rating]]="Exceptional", 5, staff[[#This Row],[Rating]]="Above average", 4, staff[[#This Row],[Rating]]="Average", 3, staff[[#This Row],[Rating]]="Poor", 2, staff[[#This Row],[Rating]]="Very poor", 1)} -> 3 | M9: =_xlfn.XLOOKUP(staff[[#This Row],[Rating]],'Lookup Array'!$A$1:$A$5, 'Lookup Array'!$B$1:$B$5, "No Rating") -> 3
B10: Archibald Filliskirk | C10: Male | D10: 35 | E10: Average | F10: 44727 | G10: Procurement | H10: 40400 | I10: NZ | J10: =(TODAY() - staff[[#This Row],[Date Joined]]) / 365 -> 3.4876712 | K10: =ROUNDUP(IF(staff[[#This Row],[Tenure]]>2, 3%, 2%) * staff[[#This Row],[Salary]],0) -> 1212 | L10: {=_xlfn.IFS(staff[[#This Row],[Rating]]="Exceptional", 5, staff[[#This Row],[Rating]]="Above average", 4, staff[[#This Row],[Rating]]="Average", 3, staff[[#This Row],[Rating]]="Poor", 2, staff[[#This Row],[Rating]]="Very poor", 1)} -> 3 | M10: =_xlfn.XLOOKUP(staff[[#This Row],[Rating]],'Lookup Array'!$A$1:$A$5, 'Lookup Array'!$B$1:$B$5, "No Rating") -> 3 | O10: Number of staff earning over 90000 | P10: =COUNTIFS(staff[Salary], ">90000") -> 63
B11: Shobhana Samuel | C11: Male | D11: 35 | E11: Average | F11: 44666 | G11: Procurement | H11: 40400 | I11: IND | J11: =(TODAY() - staff[[#This Row],[Date Joined]]) / 365 -> 3.6547945 | K11: =ROUNDUP(IF(staff[[#This Row],[Tenure]]>2, 3%, 2%) * staff[[#This Row],[Salary]],0) -> 1212 | L11: {=_xlfn.IFS(staff[[#This Row],[Rating]]="Exceptional", 5, staff[[#This Row],[Rating]]="Above average", 4, staff[[#This Row],[Rating]]="Average", 3, staff[[#This Row],[Rating]]="Poor", 2, staff[[#This Row],[Rating]]="Very poor", 1)} -> 3 | M11: =_xlfn.XLOOKUP(staff[[#This Row],[Rating]],'Lookup Array'!$A$1:$A$5, 'Lookup Array'!$B$1:$B$5, "No Rating") -> 3 | O11: % of staff earning over 90000 | P11: =P10/P2 -> 0.3442623
B12: Crissie Cordel | C12: Female | D12: 32 | E12: Average | F12: 44611 | G12: Procurement | H12: 41570 | I12: NZ | J12: =(TODAY() - staff[[#This Row],[Date Joined]]) / 365 -> 3.8054795 | K12: =ROUNDUP(IF(staff[[#This Row],[Tenure]]>2, 3%, 2%) * staff[[#This Row],[Salary]],0) -> 1248 | L12: {=_xlfn.IFS(staff[[#This Row],[Rating]]="Exceptional", 5, staff[[#This Row],[Rating]]="Above average", 4, staff[[#This Row],[Rating]]="Average", 3, staff[[#This Row],[Rating]]="Poor", 2, staff[[#This Row],[Rating]]="Very poor", 1)} -> 3 | M12: =_xlfn.XLOOKUP(staff[[#This Row],[Rating]],'Lookup Array'!$A$1:$A$5, 'Lookup Array'!$B$1:$B$5, "No Rating") -> 3
B13: Prerana Nishita | C13: Female | D13: 32 | E13: Average | F13: 44549 | G13: Procurement | H13: 41570 | I13: IND | J13: =(TODAY() - staff[[#This Row],[Date Joined]]) / 365 -> 3.9753425 | K13: =ROUNDUP(IF(staff[[#This Row],[Tenure]]>2, 3%, 2%) * staff[[#This Row],[Salary]],0) -> 1248 | L13: {=_xlfn.IFS(staff[[#This Row],[Rating]]="Exceptional", 5, staff[[#This Row],[Rating]]="Above average", 4, staff[[#This Row],[Rating]]="Average", 3, staff[[#This Row],[Rating]]="Poor", 2, staff[[#This Row],[Rating]]="Very poor", 1)} -> 3 | M13: =_xlfn.XLOOKUP(staff[[#This Row],[Rating]],'Lookup Array'!$A$1:$A$5, 'Lookup Array'!$B$1:$B$5, "No Rating") -> 3
B14: Dotty Strutley | C14: Female | D14: 31 | E14: Average | F14: 44145 | G14: Website | H14: 41980 | I14: NZ | J14: =(TODAY() - staff[[#This Row],[Date Joined]]) / 365 -> 5.0821918 | K14: =ROUNDUP(IF(staff[[#This Row],[Tenure]]>2, 3%, 2%) * staff[[#This Row],[Salary]],0) -> 1260 | L14: {=_xlfn.IFS(staff[[#This Row],[Rating]]="Exceptional", 5, staff[[#This Row],[Rating]]="Above average", 4, staff[[#This Row],[Rating]]="Average", 3, staff[[#This Row],[Rating]]="Poor", 2, staff[[#This Row],[Rating]]="Very poor", 1)} -> 3 | M14: =_xlfn.XLOOKUP(staff[[#This Row],[Rating]],'Lookup Array'!$A$1:$A$5, 'Lookup Array'!$B$1:$B$5, "No Rating") -> 3 | O14: Information Finder:
B15: Jagajeet Viraj | C15: Female | D15: 31 | E15: Average | F15: 44084 | G15: Website | H15: 41980 | I15: IND | J15: =(TODAY() - staff[[#This Row],[Date Joined]]) / 365 -> 5.2493151 | K15: =ROUNDUP(IF(staff[[#This Row],[Tenure]]>2, 3%, 2%) * staff[[#This Row],[Salary]],0) -> 1260 | L15: {=_xlfn.IFS(staff[[#This Row],[Rating]]="Exceptional", 5, staff[[#This Row],[Rating]]="Above average", 4, staff[[#This Row],[Rating]]="Average", 3, staff[[#This Row],[Rating]]="Poor", 2, staff[[#This Row],[Rating]]="Very poor", 1)} -> 3 | M15: =_xlfn.XLOOKUP(staff[[#This Row],[Rating]],'Lookup Array'!$A$1:$A$5, 'Lookup Array'!$B$1:$B$5, "No Rating") -> 3
B16: Drusy MacCombe | C16: Male | D16: 28 | E16: Very poor | F16: 44820 | G16: Sales | H16: 43510 | I16: NZ | J16: =(TODAY() - staff[[#This Row],[Date Joined]]) / 365 -> 3.2328767 | K16: =ROUNDUP(IF(staff[[#This Row],[Tenure]]>2, 3%, 2%) * staff[[#This Row],[Salary]],0) -> 1306 | L16: {=_xlfn.IFS(staff[[#This Row],[Rating]]="Exceptional", 5, staff[[#This Row],[Rating]]="Above average", 4, staff[[#This Row],[Rating]]="Average", 3, staff[[#This Row],[Rating]]="Poor", 2, staff[[#This Row],[Rating]]="Very poor", 1)} -> 1 | M16: =_xlfn.XLOOKUP(staff[[#This Row],[Rating]],'Lookup Array'!$A$1:$A$5, 'Lookup Array'!$B$1:$B$5, "No Rating") -> 1 | O16: Barr Faughny
B17: Rupak Mehra | C17: Male | D17: 28 | E17: Very poor | F17: 44758 | G17: Sales | H17: 43510 | I17: IND | J17: =(TODAY() - staff[[#This Row],[Date Joined]]) / 365 -> 3.4027397 | K17: =ROUNDUP(IF(staff[[#This Row],[Tenure]]>2, 3%, 2%) * staff[[#This Row],[Salary]],0) -> 1306 | L17: {=_xlfn.IFS(staff[[#This Row],[Rating]]="Exceptional", 5, staff[[#This Row],[Rating]]="Above average", 4, staff[[#This Row],[Rating]]="Average", 3, staff[[#This Row],[Rating]]="Poor", 2, staff[[#This Row],[Rating]]="Very poor", 1)} -> 1 | M17: =_xlfn.XLOOKUP(staff[[#This Row],[Rating]],'Lookup Array'!$A$1:$A$5, 'Lookup Array'!$B$1:$B$5, "No Rating") -> 1
B18: Kassi Jonson | C18: Female | D18: 32 | E18: Above average | F18: 44354 | G18: Website | H18: 43840 | I18: NZ | J18: =(TODAY() - staff[[#This Row],[Date Joined]]) / 365 -> 4.509589 | K18: =ROUNDUP(IF(staff[[#This Row],[Tenure]]>2, 3%, 2%) * staff[[#This Row],[Salary]],0) -> 1316 | L18: {=_xlfn.IFS(staff[[#This Row],[Rating]]="Exceptional", 5, staff[[#This Row],[Rating]]="Above average", 4, staff[[#This Row],[Rating]]="Average", 3, staff[[#This Row],[Rating]]="Poor", 2, staff[[#This Row],[Rating]]="Very poor", 1)} -> 4 | M18: =_xlfn.XLOOKUP(staff[[#This Row],[Rating]],'Lookup Array'!$A$1:$A$5, 'Lookup Array'!$B$1:$B$5, "No Rating") -> 4 | O18: {=_xlfn.XLOOKUP(O16,staff[Name], staff[[Gender]:[Tenure]])} -> Female | P18: 42 | Q18: Exceptional | R18: 44779 | S18: Procurement | T18: 75000 | U18: NZ | V18: 3.3452055
B19: Yagna Sujeev | C19: Female | D19: 32 | E19: Above average | F19: 44293 | G19: Website | H19: 43840 | I19: IND | J19: =(TODAY() - staff[[#This Row],[Date Joined]]) / 365 -> 4.6767123 | K19: =ROUNDUP(IF(staff[[#This Row],[Tenure]]>2, 3%, 2%) * staff[[#This Row],[Salary]],0) -> 1316 | L19: {=_xlfn.IFS(staff[[#This Row],[Rating]]="Exceptional", 5, staff[[#This Row],[Rating]]="Above average", 4, staff[[#This Row],[Rating]]="Average", 3, staff[[#This Row],[Rating]]="Poor", 2, staff[[#This Row],[Rating]]="Very poor", 1)} -> 4 | M19: =_xlfn.XLOOKUP(staff[[#This Row],[Rating]],'Lookup Array'!$A$1:$A$5, 'Lookup Array'!$B$1:$B$5, "No Rating") -> 4
B20: Florinda Crace | C20: Female | D20: 32 | E20: Average | F20: 44400 | G20: HR | H20: 45510 | I20: NZ | J20: =(TODAY() - staff[[#This Row],[Date Joined]]) / 365 -> 4.3835616 | K20: =ROUNDUP(IF(staff[[#This Row],[Tenure]]>2, 3%, 2%) * staff[[#This Row],[Salary]],0) -> 1366 | L20: {=_xlfn.IFS(staff[[#This Row],[Rating]]="Exceptional", 5, staff[[#This Row],[Rating]]="Above average", 4, staff[[#This Row],[Rating]]="Average", 3, staff[[#This Row],[Rating]]="Poor", 2, staff[[#This Row],[Rating]]="Very poor", 1)} -> 3 | M20: =_xlfn.XLOOKUP(staff[[#This Row],[Rating]],'Lookup Array'!$A$1:$A$5, 'Lookup Array'!$B$1:$B$5, "No Rating") -> 3
B21: Madhavdas Buhpathi | C21: Female | D21: 32 | E21: Average | F21: 44339 | G21: HR | H21: 45510 | I21: IND | J21: =(TODAY() - staff[[#This Row],[Date Joined]]) / 365 -> 4.5506849 | K21: =ROUNDUP(IF(staff[[#This Row],[Tenure]]>2, 3%, 2%) * staff[[#This Row],[Salary]],0) -> 1366 | L21: {=_xlfn.IFS(staff[[#This Row],[Rating]]="Exceptional", 5, staff[[#This Row],[Rating]]="Above average", 4, staff[[#This Row],[Rating]]="Average", 3, staff[[#This Row],[Rating]]="Poor", 2, staff[[#This Row],[Rating]]="Very poor", 1)} -> 3 | M21: =_xlfn.XLOOKUP(staff[[#This Row],[Rating]],'Lookup Array'!$A$1:$A$5, 'Lookup Array'!$B$1:$B$5, "No Rating") -> 3 | P21: Gender: | Q21: {=TRANSPOSE(_xlfn.XLOOKUP(O16,staff[Name], staff[[Gender]:[Tenure]]))} -> Female
B22: Dell Molloy | C22: Male | D22: 26 | E22: Average | F22: 44225 | G22: Procurement | H22: 47360 | I22: NZ | J22: =(TODAY() - staff[[#This Row],[Date Joined]]) / 365 -> 4.8630137 | K22: =ROUNDUP(IF(staff[[#This Row],[Tenure]]>2, 3%, 2%) * staff[[#This Row],[Salary]],0) -> 1421 | L22: {=_xlfn.IFS(staff[[#This Row],[Rating]]="Exceptional", 5, staff[[#This Row],[Rating]]="Above average", 4, staff[[#This Row],[Rating]]="Average", 3, staff[[#This Row],[Rating]]="Poor", 2, staff[[#This Row],[Rating]]="Very poor", 1)} -> 3 | M22: =_xlfn.XLOOKUP(staff[[#This Row],[Rating]],'Lookup Array'!$A$1:$A$5, 'Lookup Array'!$B$1:$B$5, "No Rating") -> 3 | P22: Age: | Q22: 42
B23: Shiuli Sapna | C23: Male | D23: 26 | E23: Average | F23: 44164 | G23: Procurement | H23: 47360 | I23: IND | J23: =(TODAY() - staff[[#This Row],[Date Joined]]) / 365 -> 5.030137 | K23: =ROUNDUP(IF(staff[[#This Row],[Tenure]]>2, 3%, 2%) * staff[[#This Row],[Salary]],0) -> 1421 | L23: {=_xlfn.IFS(staff[[#This Row],[Rating]]="Exceptional", 5, staff[[#This Row],[Rating]]="Above average", 4, staff[[#This Row],[Rating]]="Average", 3, staff[[#This Row],[Rating]]="Poor", 2, staff[[#This Row],[Rating]]="Very poor", 1)} -> 3 | M23: =_xlfn.XLOOKUP(staff[[#This Row],[Rating]],'Lookup Array'!$A$1:$A$5, 'Lookup Array'!$B$1:$B$5, "No Rating") -> 3 | P23: Rating: | Q23: Exceptional
B24: Jan Morforth | C24: Male | D24: 28 | E24: Above average | F24: 44041 | G24: Finance | H24: 48170 | I24: NZ | J24: =(TODAY() - staff[[#This Row],[Date Joined]]) / 365 -> 5.3671233 | K24: =ROUNDUP(IF(staff[[#This Row],[Tenure]]>2, 3%, 2%) * staff[[#This Row],[Salary]],0) -> 1446 | L24: {=_xlfn.IFS(staff[[#This Row],[Rating]]="Exceptional", 5, staff[[#This Row],[Rating]]="Above average", 4, staff[[#This Row],[Rating]]="Average", 3, staff[[#This Row],[Rating]]="Poor", 2, staff[[#This Row],[Rating]]="Very poor", 1)} -> 4 | M24: =_xlfn.XLOOKUP(staff[[#This Row],[Rating]],'Lookup Array'!$A$1:$A$5, 'Lookup Array'!$B$1:$B$5, "No Rating") -> 4 | P24: Date Joined | Q24: 44779
B25: Ardhendu Abhichandra Jayakar | C25: Male | D25: 28 | E25: Above average | F25: 43980 | G25: Finance | H25: 48170 | I25: IND | J25: =(TODAY() - staff[[#This Row],[Date Joined]]) / 365 -> 5.5342466 | K25: =ROUNDUP(IF(staff[[#This Row],[Tenure]]>2, 3%, 2%) * staff[[#This Row],[Salary]],0) -> 1446 | L25: {=_xlfn.IFS(staff[[#This Row],[Rating]]="Exceptional", 5, staff[[#This Row],[Rating]]="Above average", 4, staff[[#This Row],[Rating]]="Average", 3, staff[[#This Row],[Rating]]="Poor", 2, staff[[#This Row],[Rating]]="Very poor", 1)} -> 4 | M25: =_xlfn.XLOOKUP(staff[[#This Row],[Rating]],'Lookup Array'!$A$1:$A$5, 'Lookup Array'!$B$1:$B$5, "No Rating") -> 4 | P25: Department: | Q25: Procurement
B26: Erin Androsik | C26: Male | D26: 33 | E26: Above average | F26: 44701 | G26: Procurement | H26: 48530 | I26: NZ | J26: =(TODAY() - staff[[#This Row],[Date Joined]]) / 365 -> 3.5589041 | K26: =ROUNDUP(IF(staff[[#This Row],[Tenure]]>2, 3%, 2%) * staff[[#This Row],[Salary]],0) -> 1456 | L26: {=_xlfn.IFS(staff[[#This Row],[Rating]]="Exceptional", 5, staff[[#This Row],[Rating]]="Above average", 4, staff[[#This Row],[Rating]]="Average", 3, staff[[#This Row],[Rating]]="Poor", 2, staff[[#This Row],[Rating]]="Very poor", 1)} -> 4 | M26: =_xlfn.XLOOKUP(staff[[#This Row],[Rating]],'Lookup Array'!$A$1:$A$5, 'Lookup Array'!$B$1:$B$5, "No Rating") -> 4 | P26: Salary: | Q26: 75000
B27: Piyali Mahanthapa | C27: Male | D27: 33 | E27: Above average | F27: 44640 | G27: Procurement | H27: 48530 | I27: IND | J27: =(TODAY() - staff[[#This Row],[Date Joined]]) / 365 -> 3.7260274 | K27: =ROUNDUP(IF(staff[[#This Row],[Tenure]]>2, 3%, 2%) * staff[[#This Row],[Salary]],0) -> 1456 | L27: {=_xlfn.IFS(staff[[#This Row],[Rating]]="Exceptional", 5, staff[[#This Row],[Rating]]="Above average", 4, staff[[#This Row],[Rating]]="Average", 3, staff[[#This Row],[Rating]]="Poor", 2, staff[[#This Row],[Rating]]="Very poor", 1)} -> 4 | M27: =_xlfn.XLOOKUP(staff[[#This Row],[Rating]],'Lookup Array'!$A$1:$A$5, 'Lookup Array'!$B$1:$B$5, "No Rating") -> 4 | P27: Country: | Q27: NZ
B28: Gunar Cockshoot | C28: Male | D28: 31 | E28: Average | F28: 44511 | G28: Website | H28: 48950 | I28: NZ | J28: =(TODAY() - staff[[#This Row],[Date Joined]]) / 365 -> 4.0794521 | K28: =ROUNDUP(IF(staff[[#This Row],[Tenure]]>2, 3%, 2%) * staff[[#This Row],[Salary]],0) -> 1469 | L28: {=_xlfn.IFS(staff[[#This Row],[Rating]]="Exceptional", 5, staff[[#This Row],[Rating]]="Above average", 4, staff[[#This Row],[Rating]]="Average", 3, staff[[#This Row],[Rating]]="Poor", 2, staff[[#This Row],[Rating]]="Very poor", 1)} -> 3 | M28: =_xlfn.XLOOKUP(staff[[#This Row],[Rating]],'Lookup Array'!$A$1:$A$5, 'Lookup Array'!$B$1:$B$5, "No Rating") -> 3 | P28: Tenure: | Q28: 3.3452055
B29: Amal Nimesh | C29: Male | D29: 31 | E29: Average | F29: 44450 | G29: Website | H29: 48950 | I29: IND | J29: =(TODAY() - staff[[#This Row],[Date Joined]]) / 365 -> 4.2465753 | K29: =ROUNDUP(IF(staff[[#This Row],[Tenure]]>2, 3%, 2%) * staff[[#This Row],[Salary]],0) -> 1469 | L29: {=_xlfn.IFS(staff[[#This Row],[Rating]]="Exceptional", 5, staff[[#This Row],[Rating]]="Above average", 4, staff[[#This Row],[Rating]]="Average", 3, staff[[#This Row],[Rating]]="Poor", 2, staff[[#This Row],[Rating]]="Very poor", 1)} -> 3 | M29: =_xlfn.XLOOKUP(staff[[#This Row],[Rating]],'Lookup Array'!$A$1:$A$5, 'Lookup Array'!$B$1:$B$5, "No Rating") -> 3
B30: Esmaria Denecamp | C30: Male | D30: 27 | E30: Average | F30: 44567 | G30: Finance | H30: 48980 | I30: NZ | J30: =(TODAY() - staff[[#This Row],[Date Joined]]) / 365 -> 3.9260274 | K30: =ROUNDUP(IF(staff[[#This Row],[Tenure]]>2, 3%, 2%) * staff[[#This Row],[Salary]],0) -> 1470 | L30: {=_xlfn.IFS(staff[[#This Row],[Rating]]="Exceptional", 5, staff[[#This Row],[Rating]]="Above average", 4, staff[[#This Row],[Rating]]="Average", 3, staff[[#This Row],[Rating]]="Poor", 2, staff[[#This Row],[Rating]]="Very poor", 1)} -> 3 | M30: =_xlfn.XLOOKUP(staff[[#This Row],[Rating]],'Lookup Array'!$A$1:$A$5, 'Lookup Array'!$B$1:$B$5, "No Rating") -> 3
B31: Vanmala Shriharsha | C31: Male | D31: 27 | E31: Average | F31: 44506 | G31: Finance | H31: 48980 | I31: IND | J31: =(TODAY() - staff[[#This Row],[Date Joined]]) / 365 -> 4.0931507 | K31: =ROUNDUP(IF(staff[[#This Row],[Tenure]]>2, 3%, 2%) * staff[[#This Row],[Salary]],0) -> 1470 | L31: {=_xlfn.IFS(staff[[#This Row],[Rating]]="Exceptional", 5, staff[[#This Row],[Rating]]="Above average", 4, staff[[#This Row],[Rating]]="Average", 3, staff[[#This Row],[Rating]]="Poor", 2, staff[[#This Row],[Rating]]="Very poor", 1)} -> 3 | M31: =_xlfn.XLOOKUP(staff[[#This Row],[Rating]],'Lookup Array'!$A$1:$A$5, 'Lookup Array'!$B$1:$B$5, "No Rating") -> 3 | O31: Bonus Calculation:
B32: Violante Courtonne | C32: Female | D32: 34 | E32: Poor | F32: 44721 | G32: Sales | H32: 49630 | I32: NZ | J32: =(TODAY() - staff[[#This Row],[Date Joined]]) / 365 -> 3.5041096 | K32: =ROUNDUP(IF(staff[[#This Row],[Tenure]]>2, 3%, 2%) * staff[[#This Row],[Salary]],0) -> 1489 | L32: {=_xlfn.IFS(staff[[#This Row],[Rating]]="Exceptional", 5, staff[[#This Row],[Rating]]="Above average", 4, staff[[#This Row],[Rating]]="Average", 3, staff[[#This Row],[Rating]]="Poor", 2, staff[[#This Row],[Rating]]="Very poor", 1)} -> 2 | M32: =_xlfn.XLOOKUP(staff[[#This Row],[Rating]],'Lookup Array'!$A$1:$A$5, 'Lookup Array'!$B$1:$B$5, "No Rating") -> 2 | O32: Bonus is 3% of salary, if tenure > 2. Else 2%
B33: Daruka Ghazali | C33: Female | D33: 34 | E33: Poor | F33: 44660 | G33: Sales | H33: 49630 | I33: IND | J33: =(TODAY() - staff[[#This Row],[Date Joined]]) / 365 -> 3.6712329 | K33: =ROUNDUP(IF(staff[[#This Row],[Tenure]]>2, 3%, 2%) * staff[[#This Row],[Salary]],0) -> 1489 | L33: {=_xlfn.IFS(staff[[#This Row],[Rating]]="Exceptional", 5, staff[[#This Row],[Rating]]="Above average", 4, staff[[#This Row],[Rating]]="Average", 3, staff[[#This Row],[Rating]]="Poor", 2, staff[[#This Row],[Rating]]="Very poor", 1)} -> 2 | M33: =_xlfn.XLOOKUP(staff[[#This Row],[Rating]],'Lookup Array'!$A$1:$A$5, 'Lookup Array'!$B$1:$B$5, "No Rating") -> 2
B34: Kaye Crocroft | C34: Male | D34: 24 | E34: Poor | F34: 44436 | G34: Finance | H34: 52610 | I34: NZ | J34: =(TODAY() - staff[[#This Row],[Date Joined]]) / 365 -> 4.2849315 | K34: =ROUNDUP(IF(staff[[#This Row],[Tenure]]>2, 3%, 2%) * staff[[#This Row],[Salary]],0) -> 1579 | L34: {=_xlfn.IFS(staff[[#This Row],[Rating]]="Exceptional", 5, staff[[#This Row],[Rating]]="Above average", 4, staff[[#This Row],[Rating]]="Average", 3, staff[[#This Row],[Rating]]="Poor", 2, staff[[#This Row],[Rating]]="Very poor", 1)} -> 2 | M34: =_xlfn.XLOOKUP(staff[[#This Row],[Rating]],'Lookup Array'!$A$1:$A$5, 'Lookup Array'!$B$1:$B$5, "No Rating") -> 2
B35: Gumwant Veera | C35: Male | D35: 24 | E35: Poor | F35: 44375 | G35: Finance | H35: 52610 | I35: IND | J35: =(TODAY() - staff[[#This Row],[Date Joined]]) / 365 -> 4.4520548 | K35: =ROUNDUP(IF(staff[[#This Row],[Tenure]]>2, 3%, 2%) * staff[[#This Row],[Salary]],0) -> 1579 | L35: {=_xlfn.IFS(staff[[#This Row],[Rating]]="Exceptional", 5, staff[[#This Row],[Rating]]="Above average", 4, staff[[#This Row],[Rating]]="Average", 3, staff[[#This Row],[Rating]]="Poor", 2, staff[[#This Row],[Rating]]="Very poor", 1)} -> 2 | M35: =_xlfn.XLOOKUP(staff[[#This Row],[Rating]],'Lookup Array'!$A$1:$A$5, 'Lookup Array'!$B$1:$B$5, "No Rating") -> 2
B36: Tatum Hush | C36: Female | D36: 28 | E36: Average | F36: 44357 | G36: Sales | H36: 53240 | I36: NZ | J36: =(TODAY() - staff[[#This Row],[Date Joined]]) / 365 -> 4.5013699 | K36: =ROUNDUP(IF(staff[[#This Row],[Tenure]]>2, 3%, 2%) * staff[[#This Row],[Salary]],0) -> 1598 | L36: {=_xlfn.IFS(staff[[#This Row],[Rating]]="Exceptional", 5, staff[[#This Row],[Rating]]="Above average", 4, staff[[#This Row],[Rating]]="Average", 3, staff[[#This Row],[Rating]]="Poor", 2, staff[[#This Row],[Rating]]="Very poor", 1)} -> 3 | M36: =_xlfn.XLOOKUP(staff[[#This Row],[Rating]],'Lookup Array'!$A$1:$A$5, 'Lookup Array'!$B$1:$B$5, "No Rating") -> 3
B37: Anumati Shyamari Meherhomji | C37: Female | D37: 28 | E37: Average | F37: 44296 | G37: Sales | H37: 53240 | I37: IND | J37: =(TODAY() - staff[[#This Row],[Date Joined]]) / 365 -> 4.6684932 | K37: =ROUNDUP(IF(staff[[#This Row],[Tenure]]>2, 3%, 2%) * staff[[#This Row],[Salary]],0) -> 1598 | L37: {=_xlfn.IFS(staff[[#This Row],[Rating]]="Exceptional", 5, staff[[#This Row],[Rating]]="Above average", 4, staff[[#This Row],[Rating]]="Average", 3, staff[[#This Row],[Rating]]="Poor", 2, staff[[#This Row],[Rating]]="Very poor", 1)} -> 3 | M37: =_xlfn.XLOOKUP(staff[[#This Row],[Rating]],'Lookup Array'!$A$1:$A$5, 'Lookup Array'!$B$1:$B$5, "No Rating") -> 3
B38: Hoyt D'Alesco | C38: Male | D38: 32 | E38: Average | F38: 44465 | G38: Sales | H38: 53540 | I38: NZ | J38: =(TODAY() - staff[[#This Row],[Date Joined]]) / 365 -> 4.2054795 | K38: =ROUNDUP(IF(staff[[#This Row],[Tenure]]>2, 3%, 2%) * staff[[#This Row],[Salary]],0) -> 1607 | L38: {=_xlfn.IFS(staff[[#This Row],[Rating]]="Exceptional", 5, staff[[#This Row],[Rating]]="Above average", 4, staff[[#This Row],[Rating]]="Average", 3, staff[[#This Row],[Rating]]="Poor", 2, staff[[#This Row],[Rating]]="Very poor", 1)} -> 3 | M38: =_xlfn.XLOOKUP(staff[[#This Row],[Rating]],'Lookup Array'!$A$1:$A$5, 'Lookup Array'!$B$1:$B$5, "No Rating") -> 3
B39: Zach Polon | C39: Male | D39: 26 | E39: Average | F39: 44411 | G39: Procurement | H39: 53540 | I39: NZ | J39: =(TODAY() - staff[[#This Row],[Date Joined]]) / 365 -> 4.3534247 | K39: =ROUNDUP(IF(staff[[#This Row],[Tenure]]>2, 3%, 2%) * staff[[#This Row],[Salary]],0) -> 1607 | L39: {=_xlfn.IFS(staff[[#This Row],[Rating]]="Exceptional", 5, staff[[#This Row],[Rating]]="Above average", 4, staff[[#This Row],[Rating]]="Average", 3, staff[[#This Row],[Rating]]="Poor", 2, staff[[#This Row],[Rating]]="Very poor", 1)} -> 3 | M39: =_xlfn.XLOOKUP(staff[[#This Row],[Rating]],'Lookup Array'!$A$1:$A$5, 'Lookup Array'!$B$1:$B$5, "No Rating") -> 3
B40: Geena Raghavanpillai | C40: Male | D40: 32 | E40: Average | F40: 44403 | G40: Sales | H40: 53540 | I40: IND | J40: =(TODAY() - staff[[#This Row],[Date Joined]]) / 365 -> 4.3753425 | K40: =ROUNDUP(IF(staff[[#This Row],[Tenure]]>2, 3%, 2%) * staff[[#This Row],[Salary]],0) -> 1607 | L40: {=_xlfn.IFS(staff[[#This Row],[Rating]]="Exceptional", 5, staff[[#This Row],[Rating]]="Above average", 4, staff[[#This Row],[Rating]]="Average", 3, staff[[#This Row],[Rating]]="Poor", 2, staff[[#This Row],[Rating]]="Very poor", 1)} -> 3 | M40: =_xlfn.XLOOKUP(staff[[#This Row],[Rating]],'Lookup Array'!$A$1:$A$5, 'Lookup Array'!$B$1:$B$5, "No Rating") -> 3
...

Sheet Lookup Array
A1: Exceptional | B1: 5 | D1: Lookup Array for Ratings
A2: Above average | B2: 4
A3: Average | B3: 3
A4: Poor | B4: 2
A5: Very poor | B5: 1

Sheet Rating and Salary Relationship
A3: Rating | B3: Count of Name | C3: Average Salary
A4: Exceptional | B4: 4 | C4: 92080
A5: Above average | B5: 20 | C5: 75933
A6: Average | B6: 137 | C6: 76798.759
A7: Poor | B7: 16 | C7: 78115
A8: Very poor | B8: 6 | C8: 77423.333

Sheet Information Finder v2
B2: Information Finder v2
B5: Department Name | C5: Sales
B8: Number of people in the department: | C8: =COUNTIFS(staff[Department],C5) -> 28
B14: Name | C14: Rating | D14: Salary
B15: {=_xlfn._xlws.SORT(_xlfn.CHOOSECOLS(_xlfn._xlws.FILTER(staff[], staff[Department]=C5),1,7,4),2,-1)} -> Lindy Guillet | C15: 112780 | D15: Above average
B16: Krishnakanta Vellanki | C16: 112780 | D16: Above average
B17: Rafaelita Blaksland | C17: 109160 | D17: Exceptional
B18: Sawini Chandan | C18: 109160 | D18: Exceptional
B19: Hinda Label | C19: 92700 | D19: Average
B20: Purnendu Vijayarangan | C20: 92700 | D20: Average
B21: Gray Seamon | C21: 78540 | D21: Average
B22: Shulabh Qutub Sundaramoorthy | C22: 78540 | D22: Average
B23: Gigi Bohling | C23: 74550 | D23: Average
B24: Yauvani Tarpa | C24: 74550 | D24: Average
B25: Hyacinthie Braybrooke | C25: 68900 | D25: Poor
B26: Devasree Fullara Saurin | C26: 68900 | D26: Poor
B27: Kath Bletsoe | C27: 65700 | D27: Average
... B42: Waheeda Vasuman | C42: 36040 | D42: Average

Sheet Employee counts
B1: Month/Year | C1: Count of new hires | D1: Total Employees
B2: 2020 | C2: 37 | D2: 37 | R2: Month | S2: Headcount | T2: Running Total
B3: 2021 | C3: 82 | D3: 119 | Q3: {=_xlfn.SEQUENCE(36)} -> 1 | R3: {=EDATE(DATE(2020,4,1),_xlfn.ANCHORARRAY( Q3)+0)} -> 43952 | S3: =COUNTIFS(staff[Date Joined],">="&R3, staff[Date Joined],"<="&EOMONTH(R3,0)) -> 3 | T3: =SUM($S$3:S3) -> 3
B4: 2022 | C4: 62 | D4: 181 | Q4: 2 | R4: 43983 | S4: =COUNTIFS(staff[Date Joined],">="&R4, staff[Date Joined],"<="&EOMONTH(R4,0)) -> 1 | T4: =SUM($S$3:S4) -> 4
B5: 2023 | C5: 2 | D5: 183 | Q5: 3 | R5: 44013 | S5: =COUNTIFS(staff[Date Joined],">="&R5, staff[Date Joined],"<="&EOMONTH(R5,0)) -> 5 | T5: =SUM($S$3:S5) -> 9
B6: Grand Total | C6: 183 | Q6: 4 | R6: 44044 | S6: =COUNTIFS(staff[Date Joined],">="&R6, staff[Date Joined],"<="&EOMONTH(R6,0)) -> 3 | T6: =SUM($S$3:S6) -> 12
Q7: 5 | R7: 44075 | S7: =COUNTIFS(staff[Date Joined],">="&R7, staff[Date Joined],"<="&EOMONTH(R7,0)) -> 6 | T7: =SUM($S$3:S7) -> 18
B8: Row Labels | C8: Count of Name | Q8: 6 | R8: 44105 | S8: =COUNTIFS(staff[Date Joined],">="&R8, staff[Date Joined],"<="&EOMONTH(R8,0)) -> 6 | T8: =SUM($S$3:S8) -> 24
B9: 2020 | Q9: 7 | R9: 44136 | S9: =COUNTIFS(staff[Date Joined],">="&R9, staff[Date Joined],"<="&EOMONTH(R9,0)) -> 6 | T9: =SUM($S$3:S9) -> 30
B10: May | C10: 3 | Q10: 8 | R10: 44166 | S10: =COUNTIFS(staff[Date Joined],">="&R10, staff[Date Joined],"<="&EOMONTH(R10,0)) -> 7 | T10: =SUM($S$3:S10) -> 37
B11: Jun | C11: 4 | Q11: 9 | R11: 44197 | S11: =COUNTIFS(staff[Date Joined],">="&R11, staff[Date Joined],"<="&EOMONTH(R11,0)) -> 6 | T11: =SUM($S$3:S11) -> 43
B12: Jul | C12: 9 | Q12: 10 | R12: 44228 | S12: =COUNTIFS(staff[Date Joined],">="&R12, staff[Date Joined],"<="&EOMONTH(R12,0)) -> 4 | T12: =SUM($S$3:S12) -> 47
B13: Aug | C13: 12 | Q13: 11 | R13: 44256 | S13: =COUNTIFS(staff[Date Joined],">="&R13, staff[Date Joined],"<="&EOMONTH(R13,0)) -> 9 | T13: =SUM($S$3:S13) -> 56
B14: Sep | C14: 18 | Q14: 12 | R14: 44287 | S14: =COUNTIFS(staff[Date Joined],">="&R14, staff[Date Joined],"<="&EOMONTH(R14,0)) -> 5 | T14: =SUM($S$3:S14) -> 61
B15: Oct | C15: 24 | Q15: 13 | R15: 44317 | S15: =COUNTIFS(staff[Date Joined],">="&R15, staff[Date Joined],"<="&EOMONTH(R15,0)) -> 10 | T15: =SUM($S$3:S15) -> 71
B16: Nov | C16: 30 | Q16: 14 | R16: 44348 | S16: =COUNTIFS(staff[Date Joined],">="&R16, staff[Date Joined],"<="&EOMONTH(R16,0)) -> 6 | T16: =SUM($S$3:S16) -> 77
B17: Dec | C17: 37 | Q17: 15 | R17: 44378 | S17: =COUNTIFS(staff[Date Joined],">="&R17, staff[Date Joined],"<="&EOMONTH(R17,0)) -> 13 | T17: =SUM($S$3:S17) -> 90
B18: 2021 | Q18: 16 | R18: 44409 | S18: =COUNTIFS(staff[Date Joined],">="&R18, staff[Date Joined],"<="&EOMONTH(R18,0)) -> 4 | T18: =SUM($S$3:S18) -> 94
B19: Jan | C19: 6 | Q19: 17 | R19: 44440 | S19: =COUNTIFS(staff[Date Joined],">="&R19, staff[Date Joined],"<="&EOMONTH(R19,0)) -> 11 | T19: =SUM($S$3:S19) -> 105
B20: Feb | C20: 10 | Q20: 18 | R20: 44470 | S20: =COUNTIFS(staff[Date Joined],">="&R20, staff[Date Joined],"<="&EOMONTH(R20,0)) -> 3 | T20: =SUM($S$3:S20) -> 108
B21: Mar | C21: 19 | Q21: 19 | R21: 44501 | S21: =COUNTIFS(staff[Date Joined],">="&R21, staff[Date Joined],"<="&EOMONTH(R21,0)) -> 4 | T21: =SUM($S$3:S21) -> 112
B22: Apr | C22: 24 | Q22: 20 | R22: 44531 | S22: =COUNTIFS(staff[Date Joined],">="&R22, staff[Date Joined],"<="&EOMONTH(R22,0)) -> 7 | T22: =SUM($S$3:S22) -> 119
B23: May | C23: 34 | Q23: 21 | R23: 44562 | S23: =COUNTIFS(staff[Date Joined],">="&R23, staff[Date Joined],"<="&EOMONTH(R23,0)) -> 3 | T23: =SUM($S$3:S23) -> 122
B24: Jun | C24: 40 | Q24: 22 | R24: 44593 | S24: =COUNTIFS(staff[Date Joined],">="&R24, staff[Date Joined],"<="&EOMONTH(R24,0)) -> 10 | T24: =SUM($S$3:S24) -> 132
B25: Jul | C25: 53 | Q25: 23 | R25: 44621 | S25: =COUNTIFS(staff[Date Joined],">="&R25, staff[Date Joined],"<="&EOMONTH(R25,0)) -> 9 | T25: =SUM($S$3:S25) -> 141
B26: Aug | C26: 57 | Q26: 24 | R26: 44652 | S26: =COUNTIFS(staff[Date Joined],">="&R26, staff[Date Joined],"<="&EOMONTH(R26,0)) -> 9 | T26: =SUM($S$3:S26) -> 150
B27: Sep | C27: 68 | Q27: 25 | R27: 44682 | S27: =COUNTIFS(staff[Date Joined],">="&R27, staff[Date Joined],"<="&EOMONTH(R27,0)) -> 9 | T27: =SUM($S$3:S27) -> 159
B28: Oct | C28: 71 | Q28: 26 | R28: 44713 | S28: =COUNTIFS(staff[Date Joined],">="&R28, staff[Date Joined],"<="&EOMONTH(R28,0)) -> 7 | T28: =SUM($S$3:S28) -> 166
B29: Nov | C29: 75 | Q29: 27 | R29: 44743 | S29: =COUNTIFS(staff[Date Joined],">="&R29, staff[Date Joined],"<="&EOMONTH(R29,0)) -> 5 | T29: =SUM($S$3:S29) -> 171
B30: Dec | C30: 82 | Q30: 28 | R30: 44774 | S30: =COUNTIFS(staff[Date Joined],">="&R30, staff[Date Joined],"<="&EOMONTH(R30,0)) -> 5 | T30: =SUM($S$3:S30) -> 176
B31: 2022 | Q31: 29 | R31: 44805 | S31: =COUNTIFS(staff[Date Joined],">="&R31, staff[Date Joined],"<="&EOMONTH(R31,0)) -> 2 | T31: =SUM($S$3:S31) -> 178
B32: Jan | C32: 3 | Q32: 30 | R32: 44835 | S32: =COUNTIFS(staff[Date Joined],">="&R32, staff[Date Joined],"<="&EOMONTH(R32,0)) -> 3 | T32: =SUM($S$3:S32) -> 181
B33: Feb | C33: 13 | Q33: 31 | R33: 44866 | S33: =COUNTIFS(staff[Date Joined],">="&R33, staff[Date Joined],"<="&EOMONTH(R33,0)) -> 0 | T33: =SUM($S$3:S33) -> 181
B34: Mar | C34: 22 | Q34: 32 | R34: 44896 | S34: =COUNTIFS(staff[Date Joined],">="&R34, staff[Date Joined],"<="&EOMONTH(R34,0)) -> 0 | T34: =SUM($S$3:S34) -> 181
B35: Apr | C35: 31 | Q35: 33 | R35: 44927 | S35: =COUNTIFS(staff[Date Joined],">="&R35, staff[Date Joined],"<="&EOMONTH(R35,0)) -> 0 | T35: =SUM($S$3:S35) -> 181
B36: May | C36: 40 | Q36: 34 | R36: 44958 | S36: =COUNTIFS(staff[Date Joined],">="&R36, staff[Date Joined],"<="&EOMONTH(R36,0)) -> 1 | T36: =SUM($S$3:S36) -> 182
B37: Jun | C37: 47 | Q37: 35 | R37: 44986 | S37: =COUNTIFS(staff[Date Joined],">="&R37, staff[Date Joined],"<="&EOMONTH(R37,0)) -> 0 | T37: =SUM($S$3:S37) -> 182
B38: Jul | C38: 52 | Q38: 36 | R38: 45017 | S38: =COUNTIFS(staff[Date Joined],">="&R38, staff[Date Joined],"<="&EOMONTH(R38,0)) -> 1 | T38: =SUM($S$3:S38) -> 183
B39: Aug | C39: 57
B40: Sep | C40: 59
...

Sheet Male vs Female comparison
B1: Male vs Female comparison
C4: Column Labels
B5: Values | C5: Female | D5: Male
B6: Count of Name | C6: 86 | D6: 89
B7: Average of Age | C7: 31.406977 | D7: 29.393258
B8: Average of Salary | C8: 78284.186 | D8: 74915.169
B9: Average of Tenure | C9: 4.2791972 | D9: 4.2700939

Sheet India vs NZ
E2: New Zealand | M2: India
C3: =COUNTIFS(staff[Country],"NZ") -> 91 | E3: =COUNTIFS(staff[Country],"NZ", staff[Gender],"Female")/C3 -> 0.47252747 | G3: =AVERAGEIFS(staff[Salary],staff[Country],"NZ") -> 76978.791 | K3: =COUNTIFS(staff[Country],"IND") -> 92 | M3: =COUNTIFS(staff[Country],"IND", staff[Gender],"Female")/K3 -> 0.4673913 | O3: =AVERAGEIFS(staff[Salary],staff[Country],"IND") -> 77366.522
E5: Headcount by Department
D26: For India vs NZ.

Sheet IND vs NZ pivots
B4: Country | C4: IND | E4: Country | F4: NZ
B6: Department | C6: Employees | E6: Department | F6: Employees
B7: Procurement | C7: 28 | E7: Website | F7: 27
B8: Website | C8: 27 | E8: Procurement | F8: 27
B9: Finance | C9: 19 | E9: Finance | F9: 19
B10: Sales | C10: 14 | E10: Sales | F10: 14
B11: HR | C11: 4 | E11: HR | F11: 4
B12: Grand Total | C12: 92 | E12: Grand Total | F12: 91

Sheet Salary Spread
